2018-06-14 16:32:31,419 INFO: Microblog startup [in /home/krupni/microblog/app1/__init__.py:95]
2018-06-15 13:12:37,715 INFO: Microblog startup [in /home/krupni/microblog/app1/__init__.py:95]
2018-06-15 13:12:43,369 INFO: Microblog startup [in /home/krupni/microblog/app1/__init__.py:95]
2018-06-15 13:32:34,894 INFO: Microblog startup [in /home/krupni/microblog/app1/__init__.py:95]
2018-06-16 14:13:28,730 INFO: Microblog startup [in /home/krupni/microblog/app1/__init__.py:95]
2018-06-16 14:13:41,948 INFO: Microblog startup [in /home/krupni/microblog/app1/__init__.py:95]
2018-06-16 17:09:10,100 INFO: Microblog startup [in /home/krupni/microblog/app1/__init__.py:104]
2018-06-16 17:09:28,677 INFO: Microblog startup [in /home/krupni/microblog/app1/__init__.py:104]
2018-06-16 17:11:03,398 INFO: Microblog startup [in /home/krupni/microblog/app1/__init__.py:105]
2018-06-16 17:43:46,155 INFO: Microblog startup [in /home/krupni/microblog/app1/__init__.py:105]
2018-06-16 17:46:04,450 INFO: Microblog startup [in /home/krupni/microblog/app1/__init__.py:105]
2018-06-16 17:48:09,556 INFO: Microblog startup [in /home/krupni/microblog/app1/__init__.py:105]
2018-06-16 17:48:31,356 INFO: Microblog startup [in ./app1/__init__.py:105]
2018-06-16 17:49:31,629 ERROR: Unhandled exception [in ./app1/main/tasks.py:58]
Traceback (most recent call last):
  File "./app1/main/tasks.py", line 55, in export_posts
    sync=True)
  File "./app1/email.py", line 28, in send_email
    mail.send(msg)
  File "/home/krupni/microblog/venv/lib64/python3.5/site-packages/flask_mail.py", line 491, in send
    with self.connect() as connection:
  File "/home/krupni/microblog/venv/lib64/python3.5/site-packages/flask_mail.py", line 144, in __enter__
    self.host = self.configure_host()
  File "/home/krupni/microblog/venv/lib64/python3.5/site-packages/flask_mail.py", line 158, in configure_host
    host = smtplib.SMTP(self.mail.server, self.mail.port)
  File "/usr/lib64/python3.5/smtplib.py", line 251, in __init__
    (code, msg) = self.connect(host, port)
  File "/usr/lib64/python3.5/smtplib.py", line 336, in connect
    self.sock = self._get_socket(host, port, self.timeout)
  File "/usr/lib64/python3.5/smtplib.py", line 307, in _get_socket
    self.source_address)
  File "/usr/lib64/python3.5/socket.py", line 712, in create_connection
    raise err
  File "/usr/lib64/python3.5/socket.py", line 703, in create_connection
    sock.connect(sa)
ConnectionRefusedError: [Errno 111] Connection refused
