2018-05-09 17:00:33,172 ERROR: Exception on /user/susan [GET] [in /home/krupni/microblog/venv/lib64/python3.5/site-packages/flask/app.py:1560]
Traceback (most recent call last):
  File "/home/krupni/microblog/venv/lib64/python3.5/site-packages/flask/app.py", line 1982, in wsgi_app
    response = self.full_dispatch_request()
  File "/home/krupni/microblog/venv/lib64/python3.5/site-packages/flask/app.py", line 1614, in full_dispatch_request
    rv = self.handle_user_exception(e)
  File "/home/krupni/microblog/venv/lib64/python3.5/site-packages/flask/app.py", line 1517, in handle_user_exception
    reraise(exc_type, exc_value, tb)
  File "/home/krupni/microblog/venv/lib64/python3.5/site-packages/flask/_compat.py", line 33, in reraise
    raise value
  File "/home/krupni/microblog/venv/lib64/python3.5/site-packages/flask/app.py", line 1612, in full_dispatch_request
    rv = self.dispatch_request()
  File "/home/krupni/microblog/venv/lib64/python3.5/site-packages/flask/app.py", line 1598, in dispatch_request
    return self.view_functions[rule.endpoint](**req.view_args)
  File "/home/krupni/microblog/venv/lib64/python3.5/site-packages/flask_login/utils.py", line 261, in decorated_view
    return func(*args, **kwargs)
  File "/home/krupni/microblog/app1/routes.py", line 115, in user
    page = request.agrs.get('page', 1, type=int)
  File "/home/krupni/microblog/venv/lib64/python3.5/site-packages/werkzeug/local.py", line 347, in __getattr__
    return getattr(self._get_current_object(), name)
AttributeError: 'Request' object has no attribute 'agrs'
2018-05-09 17:01:16,635 INFO: Microblog startup [in /home/krupni/microblog/app1/__init__.py:60]
2018-05-09 17:01:57,683 INFO: Microblog startup [in /home/krupni/microblog/app1/__init__.py:60]
2018-05-10 12:03:37,183 INFO: Microblog startup [in /home/krupni/microblog/app1/__init__.py:60]
2018-05-10 12:06:12,717 INFO: Microblog startup [in /home/krupni/microblog/app1/__init__.py:60]
2018-05-10 12:06:17,181 ERROR: Exception on /index [GET] [in /home/krupni/microblog/venv/lib64/python3.5/site-packages/flask/app.py:1560]
Traceback (most recent call last):
  File "/home/krupni/microblog/venv/lib64/python3.5/site-packages/flask/app.py", line 1982, in wsgi_app
    response = self.full_dispatch_request()
  File "/home/krupni/microblog/venv/lib64/python3.5/site-packages/flask/app.py", line 1614, in full_dispatch_request
    rv = self.handle_user_exception(e)
  File "/home/krupni/microblog/venv/lib64/python3.5/site-packages/flask/app.py", line 1517, in handle_user_exception
    reraise(exc_type, exc_value, tb)
  File "/home/krupni/microblog/venv/lib64/python3.5/site-packages/flask/_compat.py", line 33, in reraise
    raise value
  File "/home/krupni/microblog/venv/lib64/python3.5/site-packages/flask/app.py", line 1612, in full_dispatch_request
    rv = self.dispatch_request()
  File "/home/krupni/microblog/venv/lib64/python3.5/site-packages/flask/app.py", line 1598, in dispatch_request
    return self.view_functions[rule.endpoint](**req.view_args)
  File "/home/krupni/microblog/venv/lib64/python3.5/site-packages/flask_login/utils.py", line 261, in decorated_view
    return func(*args, **kwargs)
  File "/home/krupni/microblog/app1/routes.py", line 42, in index
    return render_template('index.html', title='Home', posts=posts.ite, form=form, next_url=next_url, prev_url=prev_url)
AttributeError: 'Pagination' object has no attribute 'ite'
2018-05-10 12:08:51,460 INFO: Microblog startup [in /home/krupni/microblog/app1/__init__.py:60]
2018-05-10 12:12:59,254 INFO: Microblog startup [in /home/krupni/microblog/app1/__init__.py:64]
2018-05-10 12:20:44,675 INFO: Microblog startup [in /home/krupni/microblog/app1/__init__.py:64]
2018-05-10 12:28:16,895 INFO: Microblog startup [in /home/krupni/microblog/app1/__init__.py:64]
2018-05-10 12:42:37,858 INFO: Microblog startup [in /home/krupni/microblog/app1/__init__.py:64]
2018-05-10 14:53:23,521 INFO: Microblog startup [in /home/krupni/microblog/app1/__init__.py:64]
2018-05-10 14:53:46,818 ERROR: Exception on /reset_password_request [GET] [in /home/krupni/microblog/venv/lib64/python3.5/site-packages/flask/app.py:1560]
Traceback (most recent call last):
  File "/home/krupni/microblog/venv/lib64/python3.5/site-packages/flask/app.py", line 1982, in wsgi_app
    response = self.full_dispatch_request()
  File "/home/krupni/microblog/venv/lib64/python3.5/site-packages/flask/app.py", line 1614, in full_dispatch_request
    rv = self.handle_user_exception(e)
  File "/home/krupni/microblog/venv/lib64/python3.5/site-packages/flask/app.py", line 1517, in handle_user_exception
    reraise(exc_type, exc_value, tb)
  File "/home/krupni/microblog/venv/lib64/python3.5/site-packages/flask/_compat.py", line 33, in reraise
    raise value
  File "/home/krupni/microblog/venv/lib64/python3.5/site-packages/flask/app.py", line 1612, in full_dispatch_request
    rv = self.dispatch_request()
  File "/home/krupni/microblog/venv/lib64/python3.5/site-packages/flask/app.py", line 1598, in dispatch_request
    return self.view_functions[rule.endpoint](**req.view_args)
  File "/home/krupni/microblog/app1/routes.py", line 176, in reset_password_request
    if current_user.is_authenticated():
TypeError: 'bool' object is not callable
2018-05-10 14:55:08,628 INFO: Microblog startup [in /home/krupni/microblog/app1/__init__.py:64]
2018-05-10 14:55:46,125 ERROR: Exception on /reset_password_request [POST] [in /home/krupni/microblog/venv/lib64/python3.5/site-packages/flask/app.py:1560]
Traceback (most recent call last):
  File "/home/krupni/microblog/venv/lib64/python3.5/site-packages/flask/app.py", line 1982, in wsgi_app
    response = self.full_dispatch_request()
  File "/home/krupni/microblog/venv/lib64/python3.5/site-packages/flask/app.py", line 1614, in full_dispatch_request
    rv = self.handle_user_exception(e)
  File "/home/krupni/microblog/venv/lib64/python3.5/site-packages/flask/app.py", line 1517, in handle_user_exception
    reraise(exc_type, exc_value, tb)
  File "/home/krupni/microblog/venv/lib64/python3.5/site-packages/flask/_compat.py", line 33, in reraise
    raise value
  File "/home/krupni/microblog/venv/lib64/python3.5/site-packages/flask/app.py", line 1612, in full_dispatch_request
    rv = self.dispatch_request()
  File "/home/krupni/microblog/venv/lib64/python3.5/site-packages/flask/app.py", line 1598, in dispatch_request
    return self.view_functions[rule.endpoint](**req.view_args)
  File "/home/krupni/microblog/app1/routes.py", line 182, in reset_password_request
    send_password_reset_email(user)
NameError: name 'send_password_reset_email' is not defined
2018-05-10 17:06:23,782 INFO: Microblog startup [in /home/krupni/microblog/app1/__init__.py:64]
2018-05-10 17:08:45,965 INFO: Microblog startup [in /home/krupni/microblog/app1/__init__.py:64]
2018-05-11 11:34:12,790 INFO: Microblog startup [in /home/krupni/microblog/app1/__init__.py:64]
2018-05-11 11:36:53,242 INFO: Microblog startup [in /home/krupni/microblog/app1/__init__.py:64]
2018-05-11 11:47:44,717 INFO: Microblog startup [in /home/krupni/microblog/app1/__init__.py:64]
2018-05-11 15:57:01,422 INFO: Microblog startup [in /home/krupni/microblog/app1/__init__.py:64]
2018-05-11 15:59:55,142 INFO: Microblog startup [in /home/krupni/microblog/app1/__init__.py:64]
