2018-05-09 11:04:05,236 ERROR: Exception on / [POST] [in /home/krupni/microblog/venv/lib64/python3.5/site-packages/flask/app.py:1560]
Traceback (most recent call last):
  File "/home/krupni/microblog/venv/lib64/python3.5/site-packages/flask/app.py", line 1982, in wsgi_app
    response = self.full_dispatch_request()
  File "/home/krupni/microblog/venv/lib64/python3.5/site-packages/flask/app.py", line 1614, in full_dispatch_request
    rv = self.handle_user_exception(e)
  File "/home/krupni/microblog/venv/lib64/python3.5/site-packages/flask/app.py", line 1517, in handle_user_exception
    reraise(exc_type, exc_value, tb)
  File "/home/krupni/microblog/venv/lib64/python3.5/site-packages/flask/_compat.py", line 33, in reraise
    raise value
  File "/home/krupni/microblog/venv/lib64/python3.5/site-packages/flask/app.py", line 1612, in full_dispatch_request
    rv = self.dispatch_request()
  File "/home/krupni/microblog/venv/lib64/python3.5/site-packages/flask/app.py", line 1598, in dispatch_request
    return self.view_functions[rule.endpoint](**req.view_args)
  File "/home/krupni/microblog/venv/lib64/python3.5/site-packages/flask_login/utils.py", line 261, in decorated_view
    return func(*args, **kwargs)
  File "/home/krupni/microblog/app1/routes.py", line 24, in index
    if form.validate_on_submit():
  File "/home/krupni/microblog/venv/lib64/python3.5/site-packages/flask_wtf/form.py", line 101, in validate_on_submit
    return self.is_submitted() and self.validate()
  File "/home/krupni/microblog/venv/lib64/python3.5/site-packages/wtforms/form.py", line 310, in validate
    return super(Form, self).validate(extra)
  File "/home/krupni/microblog/venv/lib64/python3.5/site-packages/wtforms/form.py", line 152, in validate
    if not field.validate(self, extra):
  File "/home/krupni/microblog/venv/lib64/python3.5/site-packages/wtforms/fields/core.py", line 204, in validate
    stop_validation = self._run_validation_chain(form, chain)
  File "/home/krupni/microblog/venv/lib64/python3.5/site-packages/wtforms/fields/core.py", line 224, in _run_validation_chain
    validator(form, self)
TypeError: __init__() takes from 1 to 2 positional arguments but 3 were given
2018-05-09 11:04:58,988 INFO: Microblog startup [in /home/krupni/microblog/app1/__init__.py:60]
2018-05-09 11:05:10,599 ERROR: Exception on / [POST] [in /home/krupni/microblog/venv/lib64/python3.5/site-packages/flask/app.py:1560]
Traceback (most recent call last):
  File "/home/krupni/microblog/venv/lib64/python3.5/site-packages/flask/app.py", line 1982, in wsgi_app
    response = self.full_dispatch_request()
  File "/home/krupni/microblog/venv/lib64/python3.5/site-packages/flask/app.py", line 1614, in full_dispatch_request
    rv = self.handle_user_exception(e)
  File "/home/krupni/microblog/venv/lib64/python3.5/site-packages/flask/app.py", line 1517, in handle_user_exception
    reraise(exc_type, exc_value, tb)
  File "/home/krupni/microblog/venv/lib64/python3.5/site-packages/flask/_compat.py", line 33, in reraise
    raise value
  File "/home/krupni/microblog/venv/lib64/python3.5/site-packages/flask/app.py", line 1612, in full_dispatch_request
    rv = self.dispatch_request()
  File "/home/krupni/microblog/venv/lib64/python3.5/site-packages/flask/app.py", line 1598, in dispatch_request
    return self.view_functions[rule.endpoint](**req.view_args)
  File "/home/krupni/microblog/venv/lib64/python3.5/site-packages/flask_login/utils.py", line 261, in decorated_view
    return func(*args, **kwargs)
  File "/home/krupni/microblog/app1/routes.py", line 24, in index
    if form.validate_on_submit():
  File "/home/krupni/microblog/venv/lib64/python3.5/site-packages/flask_wtf/form.py", line 101, in validate_on_submit
    return self.is_submitted() and self.validate()
  File "/home/krupni/microblog/venv/lib64/python3.5/site-packages/wtforms/form.py", line 310, in validate
    return super(Form, self).validate(extra)
  File "/home/krupni/microblog/venv/lib64/python3.5/site-packages/wtforms/form.py", line 152, in validate
    if not field.validate(self, extra):
  File "/home/krupni/microblog/venv/lib64/python3.5/site-packages/wtforms/fields/core.py", line 204, in validate
    stop_validation = self._run_validation_chain(form, chain)
  File "/home/krupni/microblog/venv/lib64/python3.5/site-packages/wtforms/fields/core.py", line 224, in _run_validation_chain
    validator(form, self)
TypeError: __init__() takes from 1 to 2 positional arguments but 3 were given
2018-05-09 11:06:04,866 INFO: Microblog startup [in /home/krupni/microblog/app1/__init__.py:60]
2018-05-09 11:06:15,931 ERROR: Exception on / [POST] [in /home/krupni/microblog/venv/lib64/python3.5/site-packages/flask/app.py:1560]
Traceback (most recent call last):
  File "/home/krupni/microblog/venv/lib64/python3.5/site-packages/flask/app.py", line 1982, in wsgi_app
    response = self.full_dispatch_request()
  File "/home/krupni/microblog/venv/lib64/python3.5/site-packages/flask/app.py", line 1614, in full_dispatch_request
    rv = self.handle_user_exception(e)
  File "/home/krupni/microblog/venv/lib64/python3.5/site-packages/flask/app.py", line 1517, in handle_user_exception
    reraise(exc_type, exc_value, tb)
  File "/home/krupni/microblog/venv/lib64/python3.5/site-packages/flask/_compat.py", line 33, in reraise
    raise value
  File "/home/krupni/microblog/venv/lib64/python3.5/site-packages/flask/app.py", line 1612, in full_dispatch_request
    rv = self.dispatch_request()
  File "/home/krupni/microblog/venv/lib64/python3.5/site-packages/flask/app.py", line 1598, in dispatch_request
    return self.view_functions[rule.endpoint](**req.view_args)
  File "/home/krupni/microblog/venv/lib64/python3.5/site-packages/flask_login/utils.py", line 261, in decorated_view
    return func(*args, **kwargs)
  File "/home/krupni/microblog/app1/routes.py", line 24, in index
    if form.validate_on_submit():
  File "/home/krupni/microblog/venv/lib64/python3.5/site-packages/flask_wtf/form.py", line 101, in validate_on_submit
    return self.is_submitted() and self.validate()
  File "/home/krupni/microblog/venv/lib64/python3.5/site-packages/wtforms/form.py", line 310, in validate
    return super(Form, self).validate(extra)
  File "/home/krupni/microblog/venv/lib64/python3.5/site-packages/wtforms/form.py", line 152, in validate
    if not field.validate(self, extra):
  File "/home/krupni/microblog/venv/lib64/python3.5/site-packages/wtforms/fields/core.py", line 204, in validate
    stop_validation = self._run_validation_chain(form, chain)
  File "/home/krupni/microblog/venv/lib64/python3.5/site-packages/wtforms/fields/core.py", line 224, in _run_validation_chain
    validator(form, self)
TypeError: __init__() takes from 1 to 2 positional arguments but 3 were given
2018-05-09 11:10:52,888 INFO: Microblog startup [in /home/krupni/microblog/app1/__init__.py:60]
2018-05-09 11:11:06,663 ERROR: Exception on / [POST] [in /home/krupni/microblog/venv/lib64/python3.5/site-packages/flask/app.py:1560]
Traceback (most recent call last):
  File "/home/krupni/microblog/venv/lib64/python3.5/site-packages/flask/app.py", line 1982, in wsgi_app
    response = self.full_dispatch_request()
  File "/home/krupni/microblog/venv/lib64/python3.5/site-packages/flask/app.py", line 1614, in full_dispatch_request
    rv = self.handle_user_exception(e)
  File "/home/krupni/microblog/venv/lib64/python3.5/site-packages/flask/app.py", line 1517, in handle_user_exception
    reraise(exc_type, exc_value, tb)
  File "/home/krupni/microblog/venv/lib64/python3.5/site-packages/flask/_compat.py", line 33, in reraise
    raise value
  File "/home/krupni/microblog/venv/lib64/python3.5/site-packages/flask/app.py", line 1612, in full_dispatch_request
    rv = self.dispatch_request()
  File "/home/krupni/microblog/venv/lib64/python3.5/site-packages/flask/app.py", line 1598, in dispatch_request
    return self.view_functions[rule.endpoint](**req.view_args)
  File "/home/krupni/microblog/venv/lib64/python3.5/site-packages/flask_login/utils.py", line 261, in decorated_view
    return func(*args, **kwargs)
  File "/home/krupni/microblog/app1/routes.py", line 24, in index
    if form.validate_on_submit():
  File "/home/krupni/microblog/venv/lib64/python3.5/site-packages/flask_wtf/form.py", line 101, in validate_on_submit
    return self.is_submitted() and self.validate()
  File "/home/krupni/microblog/venv/lib64/python3.5/site-packages/wtforms/form.py", line 310, in validate
    return super(Form, self).validate(extra)
  File "/home/krupni/microblog/venv/lib64/python3.5/site-packages/wtforms/form.py", line 152, in validate
    if not field.validate(self, extra):
  File "/home/krupni/microblog/venv/lib64/python3.5/site-packages/wtforms/fields/core.py", line 204, in validate
    stop_validation = self._run_validation_chain(form, chain)
  File "/home/krupni/microblog/venv/lib64/python3.5/site-packages/wtforms/fields/core.py", line 224, in _run_validation_chain
    validator(form, self)
TypeError: __init__() takes from 1 to 2 positional arguments but 3 were given
2018-05-09 11:22:52,213 INFO: Microblog startup [in /home/krupni/microblog/app1/__init__.py:60]
2018-05-09 11:28:06,644 INFO: Microblog startup [in /home/krupni/microblog/app1/__init__.py:60]
