2018-05-15 16:29:25,525 ERROR: Exception on /user/susan [GET] [in /home/krupni/microblog/venv/lib64/python3.5/site-packages/flask/app.py:1560]
Traceback (most recent call last):
  File "/home/krupni/microblog/venv/lib64/python3.5/site-packages/flask/app.py", line 1982, in wsgi_app
    response = self.full_dispatch_request()
  File "/home/krupni/microblog/venv/lib64/python3.5/site-packages/flask/app.py", line 1614, in full_dispatch_request
    rv = self.handle_user_exception(e)
  File "/home/krupni/microblog/venv/lib64/python3.5/site-packages/flask/app.py", line 1517, in handle_user_exception
    reraise(exc_type, exc_value, tb)
  File "/home/krupni/microblog/venv/lib64/python3.5/site-packages/flask/_compat.py", line 33, in reraise
    raise value
  File "/home/krupni/microblog/venv/lib64/python3.5/site-packages/flask/app.py", line 1612, in full_dispatch_request
    rv = self.dispatch_request()
  File "/home/krupni/microblog/venv/lib64/python3.5/site-packages/flask/app.py", line 1598, in dispatch_request
    return self.view_functions[rule.endpoint](**req.view_args)
  File "/home/krupni/microblog/venv/lib64/python3.5/site-packages/flask_login/utils.py", line 261, in decorated_view
    return func(*args, **kwargs)
  File "/home/krupni/microblog/app1/routes.py", line 123, in user
    return render_template('user.html', user=user, posts=posts.items, next_url=next_url, prev_url=prev_url)
  File "/home/krupni/microblog/venv/lib64/python3.5/site-packages/flask/templating.py", line 134, in render_template
    context, ctx.app)
  File "/home/krupni/microblog/venv/lib64/python3.5/site-packages/flask/templating.py", line 116, in _render
    rv = template.render(context)
  File "/home/krupni/microblog/venv/lib64/python3.5/site-packages/jinja2/environment.py", line 1008, in render
    return self.environment.handle_exception(exc_info, True)
  File "/home/krupni/microblog/venv/lib64/python3.5/site-packages/jinja2/environment.py", line 780, in handle_exception
    reraise(exc_type, exc_value, tb)
  File "/home/krupni/microblog/venv/lib64/python3.5/site-packages/jinja2/_compat.py", line 37, in reraise
    raise value.with_traceback(tb)
  File "/home/krupni/microblog/app1/templates/user.html", line 1, in top-level template code
    {% extends 'base.html' %}
  File "/home/krupni/microblog/app1/templates/base.html", line 20, in top-level template code
    {% extends 'bootstrap/base.html' %}
  File "/home/krupni/microblog/venv/lib64/python3.5/site-packages/flask_bootstrap/templates/bootstrap/base.html", line 1, in top-level template code
    {% block doc -%}
  File "/home/krupni/microblog/venv/lib64/python3.5/site-packages/flask_bootstrap/templates/bootstrap/base.html", line 4, in block "doc"
    {%- block html %}
  File "/home/krupni/microblog/venv/lib64/python3.5/site-packages/flask_bootstrap/templates/bootstrap/base.html", line 20, in block "html"
    {% block body -%}
  File "/home/krupni/microblog/venv/lib64/python3.5/site-packages/flask_bootstrap/templates/bootstrap/base.html", line 23, in block "body"
    {% block content -%}
  File "/home/krupni/microblog/app1/templates/base.html", line 73, in block "content"
    {% block app_content %}
  File "/home/krupni/microblog/app1/templates/user.html", line 31, in block "app_content"
    <p>{{ user.followers.count() }} followers, {{ user.followed.count() }} following.</p>
  File "/home/krupni/microblog/venv/lib64/python3.5/site-packages/jinja2/environment.py", line 430, in getattr
    return getattr(obj, attribute)
jinja2.exceptions.UndefinedError: 'app1.models.User object' has no attribute 'followed'
2018-05-15 16:31:09,714 INFO: Microblog startup [in /home/krupni/microblog/app1/__init__.py:67]
2018-05-15 17:44:43,948 INFO: Microblog startup [in /home/krupni/microblog/app1/__init__.py:70]
