2018-06-05 10:12:04,704 ERROR: Exception on /index [GET] [in /home/krupni/microblog/venv/lib64/python3.5/site-packages/flask/app.py:1560]
Traceback (most recent call last):
  File "/home/krupni/microblog/venv/lib64/python3.5/site-packages/flask/app.py", line 1982, in wsgi_app
    response = self.full_dispatch_request()
  File "/home/krupni/microblog/venv/lib64/python3.5/site-packages/flask/app.py", line 1614, in full_dispatch_request
    rv = self.handle_user_exception(e)
  File "/home/krupni/microblog/venv/lib64/python3.5/site-packages/flask/app.py", line 1517, in handle_user_exception
    reraise(exc_type, exc_value, tb)
  File "/home/krupni/microblog/venv/lib64/python3.5/site-packages/flask/_compat.py", line 33, in reraise
    raise value
  File "/home/krupni/microblog/venv/lib64/python3.5/site-packages/flask/app.py", line 1612, in full_dispatch_request
    rv = self.dispatch_request()
  File "/home/krupni/microblog/venv/lib64/python3.5/site-packages/flask/app.py", line 1598, in dispatch_request
    return self.view_functions[rule.endpoint](**req.view_args)
  File "/home/krupni/microblog/venv/lib64/python3.5/site-packages/flask_login/utils.py", line 261, in decorated_view
    return func(*args, **kwargs)
  File "/home/krupni/microblog/app1/main/routes.py", line 55, in index
    prev_url=prev_url)
  File "/home/krupni/microblog/venv/lib64/python3.5/site-packages/flask/templating.py", line 134, in render_template
    context, ctx.app)
  File "/home/krupni/microblog/venv/lib64/python3.5/site-packages/flask/templating.py", line 116, in _render
    rv = template.render(context)
  File "/home/krupni/microblog/venv/lib64/python3.5/site-packages/jinja2/environment.py", line 1008, in render
    return self.environment.handle_exception(exc_info, True)
  File "/home/krupni/microblog/venv/lib64/python3.5/site-packages/jinja2/environment.py", line 780, in handle_exception
    reraise(exc_type, exc_value, tb)
  File "/home/krupni/microblog/venv/lib64/python3.5/site-packages/jinja2/_compat.py", line 37, in reraise
    raise value.with_traceback(tb)
  File "/home/krupni/microblog/app1/templates/main/index.html", line 1, in top-level template code
    {% extends "base.html" %}
  File "/home/krupni/microblog/venv/lib64/python3.5/site-packages/flask/templating.py", line 57, in get_source
    return self._get_source_fast(environment, template)
  File "/home/krupni/microblog/venv/lib64/python3.5/site-packages/flask/templating.py", line 85, in _get_source_fast
    raise TemplateNotFound(template)
jinja2.exceptions.TemplateNotFound: base.html
2018-06-05 10:14:03,230 INFO: Microblog startup [in /home/krupni/microblog/app1/__init__.py:90]
2018-06-05 11:54:57,788 INFO: Microblog startup [in /home/krupni/microblog/app1/__init__.py:90]
2018-06-05 11:55:50,118 INFO: Microblog startup [in /home/krupni/microblog/app1/__init__.py:90]
2018-06-06 16:26:10,176 INFO: Microblog startup [in /home/krupni/microblog/app1/__init__.py:95]
2018-06-06 19:18:28,317 INFO: Microblog startup [in /home/krupni/microblog/app1/__init__.py:95]
2018-06-07 11:45:11,372 INFO: Microblog startup [in /home/krupni/microblog/app1/__init__.py:95]
2018-06-07 12:31:10,578 INFO: Microblog startup [in /home/krupni/microblog/app1/__init__.py:95]
2018-06-12 15:02:18,806 INFO: Microblog startup [in /home/krupni/microblog/app1/__init__.py:95]
2018-06-12 15:22:22,419 INFO: Microblog startup [in /home/krupni/microblog/app1/__init__.py:95]
2018-06-12 17:23:30,709 INFO: Microblog startup [in /home/krupni/microblog/app1/__init__.py:95]
2018-06-13 12:37:21,253 INFO: Microblog startup [in /home/krupni/microblog/app1/__init__.py:95]
2018-06-14 13:55:11,600 INFO: Microblog startup [in /home/krupni/microblog/app1/__init__.py:95]
2018-06-14 13:55:34,458 INFO: Microblog startup [in /home/krupni/microblog/app1/__init__.py:95]
2018-06-14 13:57:28,369 INFO: Microblog startup [in /home/krupni/microblog/app1/__init__.py:95]
2018-06-14 13:57:33,539 ERROR: Exception on /messages [GET] [in /home/krupni/microblog/venv/lib64/python3.5/site-packages/flask/app.py:1560]
Traceback (most recent call last):
  File "/home/krupni/microblog/venv/lib64/python3.5/site-packages/flask/app.py", line 1982, in wsgi_app
    response = self.full_dispatch_request()
  File "/home/krupni/microblog/venv/lib64/python3.5/site-packages/flask/app.py", line 1614, in full_dispatch_request
    rv = self.handle_user_exception(e)
  File "/home/krupni/microblog/venv/lib64/python3.5/site-packages/flask/app.py", line 1517, in handle_user_exception
    reraise(exc_type, exc_value, tb)
  File "/home/krupni/microblog/venv/lib64/python3.5/site-packages/flask/_compat.py", line 33, in reraise
    raise value
  File "/home/krupni/microblog/venv/lib64/python3.5/site-packages/flask/app.py", line 1612, in full_dispatch_request
    rv = self.dispatch_request()
  File "/home/krupni/microblog/venv/lib64/python3.5/site-packages/flask/app.py", line 1598, in dispatch_request
    return self.view_functions[rule.endpoint](**req.view_args)
  File "/home/krupni/microblog/app1/main/routes.py", line 210, in messages
    current_user.add_notification("unread_message_count", 0)
  File "/home/krupni/microblog/venv/lib64/python3.5/site-packages/werkzeug/local.py", line 347, in __getattr__
    return getattr(self._get_current_object(), name)
AttributeError: 'User' object has no attribute 'add_notification'
2018-06-14 13:59:05,910 ERROR: Exception on /messages [GET] [in /home/krupni/microblog/venv/lib64/python3.5/site-packages/flask/app.py:1560]
Traceback (most recent call last):
  File "/home/krupni/microblog/venv/lib64/python3.5/site-packages/flask/app.py", line 1982, in wsgi_app
    response = self.full_dispatch_request()
  File "/home/krupni/microblog/venv/lib64/python3.5/site-packages/flask/app.py", line 1614, in full_dispatch_request
    rv = self.handle_user_exception(e)
  File "/home/krupni/microblog/venv/lib64/python3.5/site-packages/flask/app.py", line 1517, in handle_user_exception
    reraise(exc_type, exc_value, tb)
  File "/home/krupni/microblog/venv/lib64/python3.5/site-packages/flask/_compat.py", line 33, in reraise
    raise value
  File "/home/krupni/microblog/venv/lib64/python3.5/site-packages/flask/app.py", line 1612, in full_dispatch_request
    rv = self.dispatch_request()
  File "/home/krupni/microblog/venv/lib64/python3.5/site-packages/flask/app.py", line 1598, in dispatch_request
    return self.view_functions[rule.endpoint](**req.view_args)
  File "/home/krupni/microblog/app1/main/routes.py", line 210, in messages
    current_user.add_notification("unread_message_count", 0)
  File "/home/krupni/microblog/venv/lib64/python3.5/site-packages/werkzeug/local.py", line 347, in __getattr__
    return getattr(self._get_current_object(), name)
AttributeError: 'User' object has no attribute 'add_notification'
2018-06-14 14:02:02,766 ERROR: Exception on /messages [GET] [in /home/krupni/microblog/venv/lib64/python3.5/site-packages/flask/app.py:1560]
Traceback (most recent call last):
  File "/home/krupni/microblog/venv/lib64/python3.5/site-packages/flask/app.py", line 1982, in wsgi_app
    response = self.full_dispatch_request()
  File "/home/krupni/microblog/venv/lib64/python3.5/site-packages/flask/app.py", line 1614, in full_dispatch_request
    rv = self.handle_user_exception(e)
  File "/home/krupni/microblog/venv/lib64/python3.5/site-packages/flask/app.py", line 1517, in handle_user_exception
    reraise(exc_type, exc_value, tb)
  File "/home/krupni/microblog/venv/lib64/python3.5/site-packages/flask/_compat.py", line 33, in reraise
    raise value
  File "/home/krupni/microblog/venv/lib64/python3.5/site-packages/flask/app.py", line 1612, in full_dispatch_request
    rv = self.dispatch_request()
  File "/home/krupni/microblog/venv/lib64/python3.5/site-packages/flask/app.py", line 1598, in dispatch_request
    return self.view_functions[rule.endpoint](**req.view_args)
  File "/home/krupni/microblog/app1/main/routes.py", line 210, in messages
    current_user.add_notification("unread_message_count", 0)
  File "/home/krupni/microblog/venv/lib64/python3.5/site-packages/werkzeug/local.py", line 347, in __getattr__
    return getattr(self._get_current_object(), name)
AttributeError: 'User' object has no attribute 'add_notification'
2018-06-14 14:09:33,522 ERROR: Exception on /messages [GET] [in /home/krupni/microblog/venv/lib64/python3.5/site-packages/flask/app.py:1560]
Traceback (most recent call last):
  File "/home/krupni/microblog/venv/lib64/python3.5/site-packages/flask/app.py", line 1982, in wsgi_app
    response = self.full_dispatch_request()
  File "/home/krupni/microblog/venv/lib64/python3.5/site-packages/flask/app.py", line 1614, in full_dispatch_request
    rv = self.handle_user_exception(e)
  File "/home/krupni/microblog/venv/lib64/python3.5/site-packages/flask/app.py", line 1517, in handle_user_exception
    reraise(exc_type, exc_value, tb)
  File "/home/krupni/microblog/venv/lib64/python3.5/site-packages/flask/_compat.py", line 33, in reraise
    raise value
  File "/home/krupni/microblog/venv/lib64/python3.5/site-packages/flask/app.py", line 1612, in full_dispatch_request
    rv = self.dispatch_request()
  File "/home/krupni/microblog/venv/lib64/python3.5/site-packages/flask/app.py", line 1598, in dispatch_request
    return self.view_functions[rule.endpoint](**req.view_args)
  File "/home/krupni/microblog/app1/main/routes.py", line 210, in messages
    current_user.add_notification("unread_message_count", 0)
  File "/home/krupni/microblog/venv/lib64/python3.5/site-packages/werkzeug/local.py", line 347, in __getattr__
    return getattr(self._get_current_object(), name)
AttributeError: 'User' object has no attribute 'add_notification'
2018-06-14 14:15:05,028 INFO: Microblog startup [in /home/krupni/microblog/app1/__init__.py:95]
2018-06-14 14:17:56,568 INFO: Microblog startup [in /home/krupni/microblog/app1/__init__.py:95]
2018-06-14 14:25:17,677 INFO: Microblog startup [in /home/krupni/microblog/app1/__init__.py:95]
2018-06-14 14:25:51,221 INFO: Microblog startup [in /home/krupni/microblog/app1/__init__.py:95]
2018-06-14 16:32:26,105 INFO: Microblog startup [in /home/krupni/microblog/app1/__init__.py:95]
